<?xml version="1.0" ?>
<robot name="mobile_manipulator">
<link name="base_link">
<visual>
<origin xyz="0 0 0" rpy="0 0 0"/>
<geometry>
<box size="0.42 0.25 0.12"/>
</geometry>
</visual>
<collision>
<origin xyz="0 0 0" rpy="0 0 0"/>
<geometry>
<box size="0.42 0.25 0.12"/>
</geometry>
</collision>
<inertial>
<origin xyz="0 0 0" rpy="0 0 0" />
<mass value="5" />
<inertia ixx="1.340e-1"
ixy="0.0" iyy="1.713e-1"
ixz="0.0" iyz="1.815e-3" izz="5.917e-2" />
</inertial>
</link>
<gazebo reference="base_link">
<material>Gazebo/White</material>
<turnGravityOff>false</turnGravityOff>
</gazebo>

<link name="link1">
<visual>
<origin rpy="0 0 0" xyz="0 0 0.05" />
<geometry>
<cylinder length="0.10" radius="0.10" />
</geometry>
=
</visual>
<collision>
<origin rpy="0 0 0" xyz="0 0 0.05" />
<geometry>
<cylinder length="0.10" radius="0.10" />
</geometry>
</collision>
<inertial>
<mass value="0.1" />
<inertia ixx="0.03" iyy="0.03" izz="0.03" ixy="0.0" ixz="0.0" iyz="0.0" />
</inertial>

</link>
<gazebo reference="link1">
<material>Gazebo/Black</material>
<turnGravityOff>false</turnGravityOff>
</gazebo>
<joint name="joint1" type="continuous">
<origin rpy="0 0 0" xyz="0 0 0.15" />
<parent link="base_link" />
<child link="link1" />
<axis xyz="0 0 1" />
</joint>
<link name="link2">
<visual>
<origin rpy="0 0 0" xyz="0 0 0.15" />
<geometry>
<cylinder length="0.30" radius="0.03" />
</geometry>
</visual>
<collision>
<origin rpy="0 0 0" xyz="0 0 0.15" />
<geometry>
<cylinder length="0.30" radius="0.03" />
</geometry>
</collision>
<inertial>
<mass value="0.1" />
<inertia ixx="0.03" iyy="0.03" izz="0.03" ixy="0.0" ixz="0.0" iyz="0.0" />
</inertial>

</link>
<gazebo reference="link2">
<material>Gazebo/Blue</material>
<turnGravityOff>false</turnGravityOff>
</gazebo>
<joint name="joint2" type="revolute">
<origin rpy="0 0 0" xyz="0 0 0.08" />
<parent link="link1" />
<child link="link2" />
<axis xyz="0 1 0" />
<limit lower="-1.57" upper="1.57" effort="100" velocity="1" />
<dynamics damping="0.01" friction="0.01" />
</joint>
<link name="link3">
<visual>
<origin rpy="0 0 0" xyz="0 0 0.15" />
<geometry>
<cylinder length="0.30" radius="0.03" />
</geometry>
</visual>
<collision>
<origin rpy="0 0 0" xyz="0 0 0.15" />
<geometry>
<cylinder length="0.30" radius="0.03" />
</geometry>
</collision>
<inertial>
<mass value="0.1" />
<inertia ixx="0.03" iyy="0.03" izz="0.03" ixy="0.0" ixz="0.0" iyz="0.0" />
</inertial>

</link>
<gazebo reference="link3">
<material>Gazebo/Black</material>
<turnGravityOff>false</turnGravityOff>
</gazebo>
<joint name="joint3" type="revolute">
<origin rpy="0 0 0" xyz="0 0 0.28" />
<parent link="link2" />
<child link="link3" />
<axis xyz="0 1 0" />
<limit lower="-2.57" upper="2.57" effort="100" velocity="1" />
<dynamics damping="0.01" friction="0.01" />
</joint>
<link name="link4">
<visual>
<origin rpy="0 0 0" xyz="0 0 0.05" />
<geometry>
<box size="0.03 0.03 0.1" />
</geometry>
</visual>
<collision>
<origin rpy="0 0 0" xyz="0 0 0.05" />
<geometry>
<box size="0.03 0.03 0.1" />
</geometry>
</collision>
<inertial>
<mass value="0.1" />
<inertia ixx="0.03" iyy="0.03" izz="0.03" ixy="0.0" ixz="0.0" iyz="0.0" />
</inertial>

</link>
<gazebo reference="link4">
<material>Gazebo/Blue</material>
<turnGravityOff>false</turnGravityOff>
</gazebo>
<joint name="joint4" type="revolute">
<origin rpy="0 0 0" xyz="0 0 0.28" />
<parent link="link3" />
<child link="link4" />
<axis xyz="0 0 1" />
<limit lower="-3.14" upper="3.14" effort="100" velocity="1" />
<dynamics damping="0.01" friction="0.01" />
</joint>
<link name="link5">
<visual>
<origin rpy="0 0 0" xyz="0 0 0.05" />
<geometry>
<box size="0.03 0.03 0.1" />
</geometry>
</visual>
<collision>
<origin rpy="0 0 0" xyz="0 0 0.05" />
<geometry>
<box size="0.03 0.03 0.1" />
</geometry>
</collision>
<inertial>
<mass value="0.1" />
<inertia ixx="0.03" iyy="0.03" izz="0.03" ixy="0.0" ixz="0.0" iyz="0.0" />
</inertial>

</link>
<gazebo reference="link5">
<material>Gazebo/Black</material>
<turnGravityOff>false</turnGravityOff>
</gazebo>
<joint name="joint5" type="revolute">
<origin rpy="0 0 0" xyz="0 0 0.08" />
<parent link="link4" />
<child link="link5" />
<axis xyz="0 1 0" />
<limit lower="-2.57" upper="2.57" effort="100" velocity="1" />
<dynamics damping="0.01" friction="0.01" />
</joint>
<link name="link6">
<visual>
<origin rpy="0 0 0" xyz="0 0 0.05" />
<geometry>
<cylinder length="0.10" radius="0.04" />
</geometry>
</visual>
<collision>
<origin rpy="0 0 0" xyz="0 0 0.05" />
<geometry>
<cylinder length="0.10" radius="0.04" />
</geometry>
</collision>
<inertial>
<mass value="0.1" />
<inertia ixx="0.03" iyy="0.03" izz="0.03" ixy="0.0" ixz="0.0" iyz="0.0" />
</inertial>

</link>
<gazebo reference="link6">
<material>Gazebo/Blue</material>
<turnGravityOff>false</turnGravityOff>
</gazebo>
<joint name="joint6" type="revolute">
<origin rpy="0 0 0" xyz="0 0 0.08" />
<parent link="link5" />
<child link="link6" />
<axis xyz="1 0 0" />
<limit lower="-2.57" upper="2.57" effort="100" velocity="1" />
<dynamics damping="0.01" friction="0.01" />
</joint>
<link name="finger1">
<visual>
<geometry>
<box size="0.01 0.01 .05" />
</geometry>
<origin rpy="0 0 0" xyz="0.005 0.005 0.025 " />
</visual>
<collision>
<geometry>
<box size="0.01 0.01 .05" />
</geometry>
<origin rpy="0 0 0" xyz="0.005 0.005 0.025" />
</collision>
<inertial>
<mass value="0.1" />
<inertia ixx="0.03" iyy="0.03" izz="0.03" ixy="0.0" ixz="0.0" iyz="0.0" />
</inertial>

</link>
<gazebo reference="finger1">
<material>Gazebo/White</material>
<turnGravityOff>false</turnGravityOff>
</gazebo>
<joint name="f_joint1" type="prismatic">
<axis xyz="0 1 0" />
<limit effort="20" lower="0.0" upper="0.020" velocity="0.2" />
<parent link="link6" />
<child link="finger1" />
<origin rpy="0 0 0" xyz="0 -0.025 0.1" />
</joint>
<link name="finger2">
<visual>
<geometry>
<box size="0.01 0.01 .05" />
</geometry>
<origin rpy="0 0 0" xyz="0.005 0.005 0.025 " />
</visual>
<collision>
<geometry>
<box size="0.01 0.01 .05" />
</geometry>
<origin rpy="0 0 0" xyz="0.005 0.005 0.025 " />
</collision>
<inertial>
<mass value="0.1" />
<inertia ixx="0.03" iyy="0.03" izz="0.03" ixy="0.0" ixz="0.0" iyz="0.0" />
</inertial>

</link>
<gazebo reference="finger2">
<material>Gazebo/White</material>
<turnGravityOff>false</turnGravityOff>
</gazebo>
<joint name="f_joint2" type="prismatic">
<axis xyz="0 1 0" />
<limit effort="20" lower="-0.020" upper="0" velocity="0.2" />
<parent link="link6" />
<child link="finger2" />
<origin rpy="0 0 0" xyz="0 0.025 0.1" />
</joint>
<link name="left_front_wheel_link">
<visual>
<origin xyz="0 0 0" rpy="1.570796327 0 0"/>
<geometry>
<cylinder length="0.07" radius="0.127"/>
</geometry>
</visual>
<collision>
<origin xyz="0 0 0" rpy="1.570796327 0 0"/>
<geometry>
<cylinder length="0.07" radius="0.127"/>
</geometry>
</collision>
<inertial>
<origin xyz="0 0 0" rpy="0 0 0"/>
<mass value="0.1" />
<inertia ixx="7.750e-3"
ixy="0.0" iyy="4.546e-3"
ixz="0.0" iyz="1.478e-5" izz="4.545e-3" />
</inertial>
</link>

<joint name="left_front_wheel_joint" type="continuous">
<parent link="base_link"/>
<child link="left_front_wheel_link"/>
<origin xyz="0.142 0.18 0" rpy="0 0 0"/>
<axis xyz="0 1 0"/>
</joint>

<link name="right_front_wheel_link">
<visual>
<origin xyz="0 0 0" rpy="1.570796327 0 0"/>
<geometry>
<cylinder length="0.07" radius="0.127"/>
</geometry>
</visual>
<collision>
<origin xyz="0 0 0" rpy="1.570796327 0 0"/>
<geometry>
<cylinder length="0.07" radius="0.127"/>
</geometry>
</collision>
<inertial>
<origin xyz="0 0 0" rpy="0 0 0"/>
<mass value="0.1" />
<inertia ixx="7.750e-3"
ixy="0.0" iyy="4.546e-3"
ixz="0.0" iyz="1.478e-5" izz="4.545e-3" />
</inertial>
</link>

<joint name="right_front_wheel_joint" type="continuous">
<parent link="base_link"/>
<child link="right_front_wheel_link"/>
<origin xyz="0.142 -0.18 0" rpy="0 0 0"/>
<axis xyz="0 1 0"/>
</joint>

<link name="left_back_wheel_link">
<visual>
<origin xyz="0 0 0" rpy="1.570796327 0 0"/>
<geometry>
<cylinder length="0.07" radius="0.127"/>
</geometry>
</visual>
<collision>
<origin xyz="0 0 0" rpy="1.570796327 0 0"/>
<geometry>
<cylinder length="0.07" radius="0.127"/>
</geometry>
</collision>
<inertial>
<origin xyz="0 0 0" rpy="0 0 0"/>
<mass value="0.1" />
<inertia ixx="7.750e-3"
ixy="0.0" iyy="4.546e-3"
ixz="0.0" iyz="1.478e-5" izz="4.545e-3" />
</inertial>
</link>

<joint name="left_back_wheel_joint" type="continuous">
<parent link="base_link"/>
<child link="left_back_wheel_link"/>
<origin xyz="-0.142 0.18 0" rpy="0 0 0"/>
<axis xyz="0 1 0"/>
</joint>

<link name="right_back_wheel_link">
<visual>
<origin xyz="0 0 0" rpy="1.570796327 0 0"/>
<geometry>
<cylinder length="0.07" radius="0.127"/>
</geometry>
</visual>
<collision>
<origin xyz="0 0 0" rpy="1.570796327 0 0"/>
<geometry>
<cylinder length="0.07" radius="0.127"/>
</geometry>
</collision>
<inertial>
<origin xyz="0 0 0" rpy="0 0 0"/>
<mass value="0.1" />
<inertia ixx="7.750e-3"
ixy="0.0" iyy="4.546e-3"
ixz="0.0" iyz="1.478e-5" izz="4.545e-3" />
</inertial>
</link>

<joint name="right_back_wheel_joint" type="continuous">
<parent link="base_link"/>
<child link="right_back_wheel_link"/>
<origin xyz="-0.142 -0.18 0" rpy="0 0 0"/>
<axis xyz="0 1 0"/>
</joint>
<link name="middle_link">
<visual>
<geometry>
<box size="0.42 0.25 0.02"/>
</geometry>
</visual>
<collision>
<geometry>
<box size="0.42 0.25 0.02"/>
</geometry>
</collision>
<inertial>
<mass value="1" />
<inertia ixx="1.340e-1"
ixy="0.0" iyy="1.713e-1"
ixz="0.0" iyz="1.815e-3" izz="5.917e-2" />
</inertial>
</link>
<joint name="middle_joint" type="fixed">
<parent link="base_link"/>
<child link="middle_link"/>
<origin xyz="0 0 0.15" rpy="0 0 0"/>
</joint>
<link name="bolt1_link">
<visual>
<geometry>
<box size="0.02 0.02 0.1"/>
</geometry>
</visual>
<collision>
<geometry>
<box size="0.02 0.02 0.1"/>
</geometry>
</collision>
<inertial>
<mass value="0.1" />
<inertia ixx="1.340e-1"
ixy="0.0" iyy="1.713e-1"
ixz="0.0" iyz="1.815e-3" izz="5.917e-2" />
</inertial>
</link>
<joint name="bolt1_joint" type="fixed">
<parent link="base_link"/>
<child link="bolt1_link"/>
<origin xyz="0.2 0.115 0.1" rpy="0 0 0"/>
</joint>
<link name="bolt2_link">
<visual>
<geometry>
<box size="0.02 0.02 0.1"/>
</geometry>
</visual>
<collision>
<geometry>
<box size="0.02 0.02 0.1"/>
</geometry>
</collision>
<inertial>
<mass value="0.1" />
<inertia ixx="1.340e-1"
ixy="0.0" iyy="1.713e-1"
ixz="0.0" iyz="1.815e-3" izz="5.917e-2" />
</inertial>
</link>
<joint name="bolt2_joint" type="fixed">
<parent link="base_link"/>
<child link="bolt2_link"/>
<origin xyz="-0.2 0.115 0.1" rpy="0 0 0"/>
</joint>
<link name="bolt3_link">
<visual>
<geometry>
<box size="0.02 0.02 0.1"/>
</geometry>
</visual>
<collision>
<geometry>
<box size="0.02 0.02 0.1"/>
</geometry>
</collision>
<inertial>
<mass value="0.1" />
<inertia ixx="1.340e-1"
ixy="0.0" iyy="1.713e-1"
ixz="0.0" iyz="1.815e-3" izz="5.917e-2" />
</inertial>
</link>
<joint name="bolt3_joint" type="fixed">
<parent link="base_link"/>
<child link="bolt3_link"/>
<origin xyz="-0.2 -0.115 0.1" rpy="0 0 0"/>
</joint>
<link name="bolt4_link">
<visual>
<geometry>
<box size="0.02 0.02 0.1"/>
</geometry>
</visual>
<collision>
<geometry>
<box size="0.02 0.02 0.1"/>
</geometry>
</collision>
<inertial>
<mass value="0.1" />
<inertia ixx="1.340e-1"
ixy="0.0" iyy="1.713e-1"
ixz="0.0" iyz="1.815e-3" izz="5.917e-2" />
</inertial>
</link>
<joint name="bolt4_joint" type="fixed">
<parent link="base_link"/>
<child link="bolt4_link"/>
<origin xyz="0.2 -0.115 0.1" rpy="0 0 0"/>
</joint>
<link name="side1_link">
<visual>
<geometry>
<box size="0.42 0.02 0.07"/>
</geometry>
</visual>
<collision>
<geometry>
<box size="0.42 0.02 0.1"/>
</geometry>
</collision>
<inertial>
<mass value="0.1" />
<inertia ixx="1.340e-1"
ixy="0.0" iyy="1.713e-1"
ixz="0.0" iyz="1.815e-3" izz="5.917e-2" />
</inertial>
</link>
<joint name="side1_joint" type="fixed">
<parent link="base_link"/>
<child link="side1_link"/>
<origin xyz="0 -0.115 0.19" rpy="0 0 0"/>
</joint>
<link name="side2_link">
<visual>
<geometry>
<box size="0.02 0.25 0.07"/>
</geometry>
</visual>
<collision>
<geometry>
<box size="0.02 0.25 0.07"/>
</geometry>
</collision>
<inertial>
<mass value="0.1" />
<inertia ixx="1.340e-1"
ixy="0.0" iyy="1.713e-1"
ixz="0.0" iyz="1.815e-3" izz="5.917e-2" />
</inertial>
</link>
<joint name="side2_joint" type="fixed">
<parent link="base_link"/>
<child link="side2_link"/>
<origin xyz="0.2 0 0.19" rpy="0 0 0"/>
</joint>
<link name="side3_link">
<visual>
<geometry>
<box size="0.42 0.02 0.07"/>
</geometry>
</visual>
<collision>
<geometry>
<box size="0.42 0.02 0.07"/>
</geometry>
</collision>
<inertial>
<mass value="0.1" />
<inertia ixx="1.340e-1"
ixy="0.0" iyy="1.713e-1"
ixz="0.0" iyz="1.815e-3" izz="5.917e-2" />
</inertial>
</link>
<joint name="side3_joint" type="fixed">
<parent link="base_link"/>
<child link="side3_link"/>
<origin xyz="0 0.115 0.19" rpy="0 0 0"/>
</joint>
<link name="side4_link">
<visual>
<geometry>
<box size="0.02 0.25 0.07"/>
</geometry>
</visual>
<collision>
<geometry>
<box size="0.02 0.25 0.07"/>
</geometry>
</collision>
<inertial>
<mass value="0.1" />
<inertia ixx="1.340e-1"
ixy="0.0" iyy="1.713e-1"
ixz="0.0" iyz="1.815e-3" izz="5.917e-2" />
</inertial>
</link>
<joint name="side4_joint" type="fixed">
<parent link="base_link"/>
<child link="side4_link"/>
<origin xyz="-0.2 0 0.19" rpy="0 0 0"/>
</joint>
<gazebo reference="base_link">
<material>Gazebo/Blue</material>
</gazebo>
<gazebo reference="left_front_wheel_link">
<material>Gazebo/DarkGrey</material>
</gazebo>
<gazebo reference="right_front_wheel_link">
<material>Gazebo/DarkGrey</material>
</gazebo>
<gazebo reference="left_back_wheel_link">
<material>Gazebo/DarkGrey</material>
</gazebo>
<gazebo reference="right_back_wheel_link">
<material>Gazebo/DarkGrey</material>
</gazebo>

<gazebo reference="bolt1_link">
<material>Gazebo/Black</material>
</gazebo>
<gazebo reference="bolt2_link">
<material>Gazebo/Black</material>
</gazebo>
<gazebo reference="bolt3_link">
<material>Gazebo/Black</material>
</gazebo>
<gazebo reference="bolt4_link">
<material>Gazebo/Black</material>

</gazebo>
<gazebo>
<plugin name="gazebo_base_controller" filename="libgazebo_ros_skid_steer_drive.so">
<updateRate>15.0</updateRate>
<robotNamespace>/</robotNamespace>
<leftFrontJoint>left_front_wheel_joint</leftFrontJoint>
<rightFrontJoint>right_front_wheel_joint</rightFrontJoint>
<leftRearJoint>left_back_wheel_joint</leftRearJoint>
<rightRearJoint>right_back_wheel_joint</rightRearJoint>
<wheelSeparation>0.358</wheelSeparation>
<wheelDiameter>0.254</wheelDiameter>
<robotBaseFrame>base_link</robotBaseFrame>
<torque>8</torque>
<commandTopic>cmd_vel</commandTopic>
<broadcastTF>false</broadcastTF>
</plugin>
</gazebo>
</robot>
